Workbook

Sheet 13.08
A1: SIM | B1: Status | C1: SKU (Sapo) | D1: SKU (mới) | E1: SKU (full) | F1: Total Inventory | H1: Quantity due to expiration | I1: Expiration | J1: Expired date left | K1: Date of Import | L1: Inventory Age | M1: Last 15 days | N1: Last 30 days | O1: Safety Stock (15D) | P1: Reorder Point (30D) | Q1: Vendor | R1: Kho tổng | T1: Phổ Quang - HCM | V1: Đống Đa - Hà Nội | X1: Tân Sơn Nhất - HCM | Z1: Chi nhánh Ký gửi | AB1: Avg Pcs/day | AC1: DOI (Số ngày tồn kho) | AD1: Estimated date out of stock | AE1: Evaluate | AF1: Retail Price | AG1: Total retail price | AH1: Near Expiration Inventory | AI1: OPS | AJ1: Telco | AK1: OD | AL1: WS | AM1: B2C | AN1: Marketing
A2: No. | F2: Stock | G2: Available for sale | M2: Sold | N2: Sold | R2: Stock | S2: Available for sale | T2: Stock | U2: Available for sale | V2: Stock | W2: Available for sale | X2: Stock | Y2: Available for sale | Z2: Stock | AA2: Available for sale
A3: 1 | B3: Temporary | C3: 3HKDATAPOOLSIM | D3: 3HKDATAPOOLSIM | E3: 1D0003DK00000 | F3: 419 | G3: 419 | I3: =VLOOKUP(C3,'Data Products'!$A:$B,2,0) | J3: =IFERROR(I3-TODAY(),"") | K3: 45723 | L3: =TODAY()-K3 | M3: 354 | N3: 380 | R3: 0 | S3: 0 | T3: 326 | U3: 326 | V3: 146 | W3: 146 | X3: 0 | Y3: 0 | Z3: 0 | AA3: 0 | AB3: =N3/30 | AC3: =IFERROR(F3/AB3,"-") | AD3: =IFERROR(TODAY()+AC3,"-") | AE3: =_xlfn.IFS(AC3="-","Not sold yet",AND(AC3<=150,AC3>60),"Out of stock more than 60 days",AC3<=60,"Out of stock less than 60 days",AC3>=150,"Out of stock more than 150 days") | AF3: =VLOOKUP(C3,'Data Products'!$A:$J,10,0) | AG3: =AF3*F3 | AH3: =IF(J3<=90,F3,0) | AI3: =IFERROR(VLOOKUP(C3,$C$3:$AI$42,34,0),"")
A4: 1 | B4: Active | C4: 1D0003DK00000 | D4: 1D0003DK00000 | E4: 1D0003DK00000 | F4: 16943 | G4: 16943 | I4: =VLOOKUP(C4,'Data Products'!$A:$B,2,0) | J4: =IFERROR(I4-TODAY(),"") | K4: 45617 | L4: =TODAY()-K4 | M4: 9349 | N4: 17734 | R4: 0 | S4: 0 | T4: 1378 | U4: 1369 | V4: 115 | W4: 112 | X4: 46 | Y4: 22 | Z4: 0 | AA4: 0 | AB4: =N4/30 | AC4: =IFERROR(F4/AB4,"-") | AD4: =IFERROR(TODAY()+AC4,"-") | AE4: =_xlfn.IFS(AC4="-","Not sold yet",AND(AC4<=150,AC4>60),"Out of stock more than 60 days",AC4<=60,"Out of stock less than 60 days",AC4>=150,"Out of stock more than 150 days") | AF4: =VLOOKUP(C4,'Data Products'!$A:$J,10,0) | AG4: =AF4*F4 | AH4: =IF(J4<=90,F4,0) | AI4: cần có hàng mới 20 - 25/08 để an toàn
A5: 2 | B5: Active | C5: 1D000BCK00000 | D5: 1D000BCK00000 | E5: 1D000BCK00000 | F5: 285 | G5: 285 | I5: =VLOOKUP(C5,'Data Products'!$A:$B,2,0) | J5: =IFERROR(I5-TODAY(),"") | K5: 45191 | L5: =TODAY()-K5 | M5: 17 | N5: 36 | R5: 0 | S5: 0 | T5: 26 | U5: 26 | V5: 416 | W5: 416 | X5: 0 | Y5: 0 | Z5: 0 | AA5: 0 | AB5: =N5/30 | AC5: =IFERROR(F5/AB5,"-") | AD5: =IFERROR(TODAY()+AC5,"-") | AE5: =_xlfn.IFS(AC5="-","Not sold yet",AND(AC5<=150,AC5>60),"Out of stock more than 60 days",AC5<=60,"Out of stock less than 60 days",AC5>=150,"Out of stock more than 150 days") | AF5: =VLOOKUP(C5,'Data Products'!$A:$J,10,0) | AG5: =AF5*F5 | AH5: =IF(J5<=90,F5,0) | AI5: sắp hết hạn, gia hạn thêm 1 tháng
A6: 3 | B6: Active | C6: 1D000ELK00000 | D6: 1D000ELK00000 | E6: 1D000ELK00000 | F6: 4268 | G6: 4268 | I6: =VLOOKUP(C6,'Data Products'!$A:$B,2,0) | J6: =IFERROR(I6-TODAY(),"") | K6: 45752 | L6: =TODAY()-K6 | M6: 28 | N6: 48 | R6: 0 | S6: 0 | T6: 1 | U6: 1 | V6: 1 | W6: 1 | X6: 0 | Y6: 0 | Z6: 0 | AA6: 0 | AB6: =N6/30 | AC6: =IFERROR(F6/AB6,"-") | AD6: =IFERROR(TODAY()+AC6,"-") | AE6: =_xlfn.IFS(AC6="-","Not sold yet",AND(AC6<=150,AC6>60),"Out of stock more than 60 days",AC6<=60,"Out of stock less than 60 days",AC6>=150,"Out of stock more than 150 days") | AF6: =VLOOKUP(C6,'Data Products'!$A:$J,10,0) | AG6: =AF6*F6 | AH6: =IF(J6<=90,F6,0) | AI6: =IFERROR(VLOOKUP(C6,$C$3:$AI$42,34,0),"")
A7: 4 | B7: Active | C7: 1D000JYK00000 | D7: 1D000JYK00000 | E7: 1D000JYK00000 | F7: 879 | G7: 859 | I7: =VLOOKUP(C7,'Data Products'!$A:$B,2,0) | J7: =IFERROR(I7-TODAY(),"") | K7: 45854 | L7: =TODAY()-K7 | M7: 3 | N7: 8 | R7: 0 | S7: 0 | T7: 288 | U7: 288 | V7: 512 | W7: 512 | X7: 20 | Y7: 20 | Z7: 0 | AA7: 0 | AB7: =N7/30 | AC7: =IFERROR(F7/AB7,"-") | AD7: =IFERROR(TODAY()+AC7,"-") | AE7: =_xlfn.IFS(AC7="-","Not sold yet",AND(AC7<=150,AC7>60),"Out of stock more than 60 days",AC7<=60,"Out of stock less than 60 days",AC7>=150,"Out of stock more than 150 days") | AF7: =VLOOKUP(C7,'Data Products'!$A:$J,10,0) | AG7: =AF7*F7 | AH7: =IF(J7<=90,F7,0) | AI7: =IFERROR(VLOOKUP(C7,$C$3:$AI$42,34,0),"")
A8: 5 | B8: Active | C8: 1D000SSK00000 | D8: 1D000SSK00000 | E8: 1D000SSK00000 | F8: 2476 | G8: 2476 | I8: =VLOOKUP(C8,'Data Products'!$A:$B,2,0) | J8: =IFERROR(I8-TODAY(),"") | K8: 45855 | L8: =TODAY()-K8 | M8: 9 | N8: 63 | R8: 0 | S8: 0 | T8: 51 | U8: 51 | V8: 101 | W8: 101 | X8: 0 | Y8: 0 | Z8: 0 | AA8: 0 | AB8: =N8/30 | AC8: =IFERROR(F8/AB8,"-") | AD8: =IFERROR(TODAY()+AC8,"-") | AE8: =_xlfn.IFS(AC8="-","Not sold yet",AND(AC8<=150,AC8>60),"Out of stock more than 60 days",AC8<=60,"Out of stock less than 60 days",AC8>=150,"Out of stock more than 150 days") | AF8: =VLOOKUP(C8,'Data Products'!$A:$J,10,0) | AG8: =AF8*F8 | AH8: =IF(J8<=90,F8,0) | AI8: =IFERROR(VLOOKUP(C8,$C$3:$AI$42,34,0)," ")
A9: 6 | B9: Active | C9: 1D000UBK00000 | D9: 1D000UBK00000 | E9: 1D000UBK00000 | F9: 2062 | G9: 2062 | I9: =VLOOKUP(C9,'Data Products'!$A:$B,2,0) | J9: =IFERROR(I9-TODAY(),"") | K9: 45856 | L9: =TODAY()-K9 | M9: 0 | N9: 0 | R9: 0 | S9: 0 | T9: 1480 | U9: 1478 | V9: 1112 | W9: 1112 | X9: 0 | Y9: 0 | Z9: 0 | AA9: 0 | AB9: =N9/30 | AC9: =IFERROR(F9/AB9,"-") | AD9: =IFERROR(TODAY()+AC9,"-") | AE9: =_xlfn.IFS(AC9="-","Not sold yet",AND(AC9<=150,AC9>60),"Out of stock more than 60 days",AC9<=60,"Out of stock less than 60 days",AC9>=150,"Out of stock more than 150 days") | AF9: =VLOOKUP(C9,'Data Products'!$A:$J,10,0) | AG9: =AF9*F9 | AH9: =IF(J9<=90,F9,0) | AI9: =IFERROR(VLOOKUP(C9,$C$3:$AI$42,34,0),"")
A10: 7 | B10: Active | C10: 1D000WMK00000 | D10: 1D000WMK00000 | E10: 1D000WMK00000 | F10: 440 | G10: 440 | I10: =VLOOKUP(C10,'Data Products'!$A:$B,2,0) | J10: =IFERROR(I10-TODAY(),"") | K10: 45857 | L10: =TODAY()-K10 | M10: 132 | N10: 223 | R10: 0 | S10: 0 | T10: 0 | U10: 0 | V10: 2 | W10: 2 | X10: 0 | Y10: 0 | Z10: 0 | AA10: 0 | AB10: =N10/30 | AC10: =IFERROR(F10/AB10,"-") | AD10: =IFERROR(TODAY()+AC10,"-") | AE10: =_xlfn.IFS(AC10="-","Not sold yet",AND(AC10<=150,AC10>60),"Out of stock more than 60 days",AC10<=60,"Out of stock less than 60 days",AC10>=150,"Out of stock more than 150 days") | AF10: =VLOOKUP(C10,'Data Products'!$A:$J,10,0) | AG10: =AF10*F10 | AH10: =IF(J10<=90,F10,0) | AI10: =IFERROR(VLOOKUP(C10,$C$3:$AI$42,34,0),"")
A11: 8 | B11: Temporary | C11: CNMCU05GBFY05D | D11: CNMCU05GBFY05D | E11: CNMCU05GBFY05D | F11: 1200 | G11: 1200 | I11: =VLOOKUP(C11,'Data Products'!$A:$B,2,0) | J11: =IFERROR(I11-TODAY(),"") | K11: 45858 | L11: =TODAY()-K11 | M11: 0 | N11: 0 | R11: 0 | S11: 0 | T11: 1289 | U11: 1289 | V11: 773 | W11: 773 | X11: 0 | Y11: 0 | Z11: 0 | AA11: 0 | AB11: =N11/30 | AC11: =IFERROR(F11/AB11,"-") | AD11: =IFERROR(TODAY()+AC11,"-") | AE11: =_xlfn.IFS(AC11="-","Not sold yet",AND(AC11<=150,AC11>60),"Out of stock more than 60 days",AC11<=60,"Out of stock less than 60 days",AC11>=150,"Out of stock more than 150 days") | AF11: =VLOOKUP(C11,'Data Products'!$A:$J,10,0) | AG11: =AF11*F11 | AH11: =IF(J11<=90,F11,0) | AI11: =IFERROR(VLOOKUP(C11,$C$3:$AI$42,34,0),"")
A12: 9 | B12: Temporary | C12: CNMCU07GBFY08D | D12: CNMCU07GBFY08D | E12: CNMCU07GBFY08D | F12: 1000 | G12: 1000 | I12: =VLOOKUP(C12,'Data Products'!$A:$B,2,0) | J12: =IFERROR(I12-TODAY(),"") | K12: 45532 | L12: =TODAY()-K12 | M12: 0 | N12: 0 | R12: 0 | S12: 0 | T12: 417 | U12: 416 | V12: 785 | W12: 785 | X12: 0 | Y12: 0 | Z12: 0 | AA12: 0 | AB12: =N12/30 | AC12: =IFERROR(F12/AB12,"-") | AD12: =IFERROR(TODAY()+AC12,"-") | AE12: =_xlfn.IFS(AC12="-","Not sold yet",AND(AC12<=150,AC12>60),"Out of stock more than 60 days",AC12<=60,"Out of stock less than 60 days",AC12>=150,"Out of stock more than 150 days") | AF12: =VLOOKUP(C12,'Data Products'!$A:$J,10,0) | AG12: =AF12*F12 | AH12: =IF(J12<=90,F12,0) | AI12: qua tết push lại, mỗi tuần nhắc lại
A13: 10 | B13: Temporary | C13: KORCU10GBFY05D | D13: KORCU10GBFY05D | E13: KORCU10GBFY05D | F13: 500 | G13: 500 | I13: =VLOOKUP(C13,'Data Products'!$A:$B,2,0) | J13: =IFERROR(I13-TODAY(),"") | K13: 45504 | L13: =TODAY()-K13 | M13: 0 | N13: 0 | R13: 0 | S13: 0 | T13: 3870 | U13: 1017 | V13: 366 | W13: 366 | X13: 0 | Y13: 0 | Z13: 0 | AA13: 0 | AB13: =N13/30 | AC13: =IFERROR(F13/AB13,"-") | AD13: =IFERROR(TODAY()+AC13,"-") | AE13: =_xlfn.IFS(AC13="-","Not sold yet",AND(AC13<=150,AC13>60),"Out of stock more than 60 days",AC13<=60,"Out of stock less than 60 days",AC13>=150,"Out of stock more than 150 days") | AF13: =VLOOKUP(C13,'Data Products'!$A:$J,10,0) | AG13: =AF13*F13 | AH13: =IF(J13<=90,F13,0) | AI13: =IFERROR(VLOOKUP(C13,$C$3:$AI$42,34,0),"")
A14: 11 | B14: Active | C14: 1DCNMCTF00705 | D14: 1DCNMCTF00705 | E14: 1ECNMCTF00705 | F14: 181 | G14: 181 | I14: =VLOOKUP(C14,'Data Products'!$A:$B,2,0) | J14: =IFERROR(I14-TODAY(),"") | K14: 45504 | L14: =TODAY()-K14 | M14: 1 | N14: 1 | R14: 1200 | S14: 1200 | T14: 0 | U14: 0 | V14: 0 | W14: 0 | X14: 0 | Y14: 0 | Z14: 0 | AA14: 0 | AB14: =N14/30 | AC14: =IFERROR(F14/AB14,"-") | AD14: =IFERROR(TODAY()+AC14,"-") | AE14: =_xlfn.IFS(AC14="-","Not sold yet",AND(AC14<=150,AC14>60),"Out of stock more than 60 days",AC14<=60,"Out of stock less than 60 days",AC14>=150,"Out of stock more than 150 days") | AF14: =VLOOKUP(C14,'Data Products'!$A:$J,10,0) | AG14: =AF14*F14 | AH14: =IF(J14<=90,F14,0) | AI14: =IFERROR(VLOOKUP(C14,$C$3:$AI$42,34,0)," ")
A15: 12 | B15: Active | C15: 1DCNMCUF01530 | D15: 1DCNMCUF01530 | E15: 1ECNMCUF01530 | F15: 98 | G15: 98 | I15: =VLOOKUP(C15,'Data Products'!$A:$B,2,0) | J15: =IFERROR(I15-TODAY(),"") | K15: 45648 | L15: =TODAY()-K15 | M15: 4 | N15: 5 | R15: 1000 | S15: 1000 | T15: 0 | U15: 0 | V15: 0 | W15: 0 | X15: 0 | Y15: 0 | Z15: 0 | AA15: 0 | AB15: =N15/30 | AC15: =IFERROR(F15/AB15,"-") | AD15: =IFERROR(TODAY()+AC15,"-") | AE15: =_xlfn.IFS(AC15="-","Not sold yet",AND(AC15<=150,AC15>60),"Out of stock more than 60 days",AC15<=60,"Out of stock less than 60 days",AC15>=150,"Out of stock more than 150 days") | AF15: =VLOOKUP(C15,'Data Products'!$A:$J,10,0) | AG15: =AF15*F15 | AH15: =IF(J15<=90,F15,0) | AI15: =IFERROR(VLOOKUP(C15,$C$3:$AI$42,34,0),"")
A16: 13 | B16: Active | C16: 1DCNMCUF00303 | D16: 1DCNMCUF00303 | E16: 1ECNMCUF00303 | F16: 846 | G16: 846 | I16: =VLOOKUP(C16,'Data Products'!$A:$B,2,0) | J16: =IFERROR(I16-TODAY(),"") | K16: 45504 | L16: =TODAY()-K16 | M16: 101 | N16: 103 | R16: 500 | S16: 500 | T16: 0 | U16: 0 | V16: 0 | W16: 0 | X16: 0 | Y16: 0 | Z16: 0 | AA16: 0 | AB16: =N16/30 | AC16: =IFERROR(F16/AB16,"-") | AD16: =IFERROR(TODAY()+AC16,"-") | AE16: =_xlfn.IFS(AC16="-","Not sold yet",AND(AC16<=150,AC16>60),"Out of stock more than 60 days",AC16<=60,"Out of stock less than 60 days",AC16>=150,"Out of stock more than 150 days") | AF16: =VLOOKUP(C16,'Data Products'!$A:$J,10,0) | AG16: =AF16*F16 | AH16: =IF(J16<=90,F16,0) | AI16: =IFERROR(VLOOKUP(C16,$C$3:$AI$42,34,0),"")
A17: 14 | B17: Active | C17: 1DCNMCUF00505 | D17: 1DCNMCUF00505 | E17: 1ECNMCUF00505 | F17: 0 | G17: 0 | I17: =VLOOKUP(C17,'Data Products'!$A:$B,2,0) | J17: =IFERROR(I17-TODAY(),"") | K17: 45653 | L17: =TODAY()-K17 | M17: 0 | N17: 0 | R17: 0 | S17: 0 | T17: 128 | U17: 128 | V17: 54 | W17: 54 | X17: 0 | Y17: 0 | Z17: 0 | AA17: 0 | AB17: =N17/30 | AC17: =IFERROR(F17/AB17,"-") | AD17: =IFERROR(TODAY()+AC17,"-") | AE17: =_xlfn.IFS(AC17="-","Not sold yet",AND(AC17<=150,AC17>60),"Out of stock more than 60 days",AC17<=60,"Out of stock less than 60 days",AC17>=150,"Out of stock more than 150 days") | AF17: =VLOOKUP(C17,'Data Products'!$A:$J,10,0) | AG17: =AF17*F17 | AH17: =IF(J17<=90,F17,0) | AI17: =IFERROR(VLOOKUP(C17,$C$3:$AI$42,34,0),"")
A18: 15 | B18: Active | C18: 1DTHADTF05010 | D18: 1DTHADTF05010 | E18: 1ETHADTF05010 | F18: 5 | G18: 5 | I18: =VLOOKUP(C18,'Data Products'!$A:$B,2,0) | J18: =IFERROR(I18-TODAY(),"") | K18: 45737 | L18: =TODAY()-K18 | M18: 0 | N18: 0 | R18: 0 | S18: 0 | T18: 0 | U18: 0 | V18: 116 | W18: 116 | X18: 0 | Y18: 0 | Z18: 0 | AA18: 0 | AB18: =N18/30 | AC18: =IFERROR(F18/AB18,"-") | AD18: =IFERROR(TODAY()+AC18,"-") | AE18: =_xlfn.IFS(AC18="-","Not sold yet",AND(AC18<=150,AC18>60),"Out of stock more than 60 days",AC18<=60,"Out of stock less than 60 days",AC18>=150,"Out of stock more than 150 days") | AF18: =VLOOKUP(C18,'Data Products'!$A:$J,10,0) | AG18: =AF18*F18 | AH18: =IF(J18<=90,F18,0)
A19: 16 | B19: Active | C19: 1DWORCBF01030 | D19: 1DWORCBF01030 | E19: 1DWORCBF01030 | F19: 323 | G19: 323 | I19: =VLOOKUP(C19,'Data Products'!$A:$B,2,0) | J19: =IFERROR(I19-TODAY(),"") | K19: 45653 | L19: =TODAY()-K19 | M19: 0 | N19: 110 | R19: 600 | S19: 600 | T19: 100 | U19: 100 | V19: 300 | W19: 300 | X19: 0 | Y19: 0 | Z19: 0 | AA19: 0 | AB19: =N19/30 | AC19: =IFERROR(F19/AB19,"-") | AD19: =IFERROR(TODAY()+AC19,"-") | AE19: =_xlfn.IFS(AC19="-","Not sold yet",AND(AC19<=150,AC19>60),"Out of stock more than 60 days",AC19<=60,"Out of stock less than 60 days",AC19>=150,"Out of stock more than 150 days") | AF19: =VLOOKUP(C19,'Data Products'!$A:$J,10,0) | AG19: =AF19*F19 | AH19: =IF(J19<=90,F19,0)
A20: 17 | B20: Active | C20: 1DTHATMF01507 | D20: 1DTHATMF01507 | E20: 1ETHATMF01507 | F20: 3969 | G20: 3969 | I20: =VLOOKUP(C20,'Data Products'!$A:$B,2,0) | J20: =IFERROR(I20-TODAY(),"") | K20: 45653 | L20: =TODAY()-K20 | M20: 738 | N20: 3160 | R20: 0 | S20: 0 | T20: 27 | U20: 27 | V20: 25 | W20: 25 | X20: 0 | Y20: 0 | Z20: 0 | AA20: 0 | AB20: =N20/30 | AC20: =IFERROR(F20/AB20,"-") | AD20: =IFERROR(TODAY()+AC20,"-") | AE20: =_xlfn.IFS(AC20="-","Not sold yet",AND(AC20<=150,AC20>60),"Out of stock more than 60 days",AC20<=60,"Out of stock less than 60 days",AC20>=150,"Out of stock more than 150 days") | AF20: =VLOOKUP(C20,'Data Products'!$A:$J,10,0) | AG20: =AF20*F20 | AH20: =IF(J20<=90,F20,0) | AI20: cần đầu tháng 9 có hàng mới
A21: 18 | B21: Active | C21: 1DTHATMF05010 | D21: 1DTHATMF05010 | E21: 1ETHATMF05010 | F21: 6918 | G21: 6918 | I21: =VLOOKUP(C21,'Data Products'!$A:$B,2,0) | J21: =IFERROR(I21-TODAY(),"") | K21: 45847 | L21: =TODAY()-K21 | M21: 518 | N21: 1375 | R21: 0 | S21: 0 | T21: 113 | U21: 106 | V21: 1097 | W21: 1097 | X21: 5 | Y21: 0 | Z21: 0 | AA21: 0 | AB21: =N21/30 | AC21: =IFERROR(F21/AB21,"-") | AD21: =IFERROR(TODAY()+AC21,"-") | AE21: =_xlfn.IFS(AC21="-","Not sold yet",AND(AC21<=150,AC21>60),"Out of stock more than 60 days",AC21<=60,"Out of stock less than 60 days",AC21>=150,"Out of stock more than 150 days") | AF21: =VLOOKUP(C21,'Data Products'!$A:$J,10,0) | AG21: =AF21*F21 | AH21: =IF(J21<=90,F21,0) | AI21: cần đầu tháng 9 có hàng mới
A22: 19 | B22: Active | C22: 1DTHATMF01507 | D22: 1DTHATMF01507 | E22: 1ETHATMF01507 | F22: 3969 | G22: 3969 | I22: =VLOOKUP(C22,'Data Products'!$A:$B,2,0) | J22: =IFERROR(I22-TODAY(),"") | K22: 45847 | L22: =TODAY()-K22 | M22: 738 | N22: 3090 | R22: 0 | S22: 0 | T22: 154 | U22: 154 | V22: 310 | W22: 310 | X22: 0 | Y22: 0 | Z22: 0 | AA22: 0 | AB22: =N22/30 | AC22: =IFERROR(F22/AB22,"-") | AD22: =IFERROR(TODAY()+AC22,"-") | AE22: =_xlfn.IFS(AC22="-","Not sold yet",AND(AC22<=150,AC22>60),"Out of stock more than 60 days",AC22<=60,"Out of stock less than 60 days",AC22>=150,"Out of stock more than 150 days") | AF22: =VLOOKUP(C22,'Data Products'!$A:$J,10,0) | AG22: =AF22*F22 | AH22: =IF(J22<=90,F22,0) | AI22: pass quý 1 push lại
A23: 20 | B23: Temporary | C23: CNMCU15GBFY30D | D23: CNMCU15GBFY30D | E23: CNMCU15GBFY30D | F23: 1500 | G23: 1500 | I23: =VLOOKUP(C23,'Data Products'!$A:$B,2,0) | J23: =IFERROR(I23-TODAY(),"") | K23: 45416 | L23: =TODAY()-K23 | M23: 0 | N23: 0 | AB23: =N23/30 | AC23: =IFERROR(F23/AB23,"-") | AD23: =IFERROR(TODAY()+AC23,"-") | AE23: =_xlfn.IFS(AC23="-","Not sold yet",AND(AC23<=150,AC23>60),"Out of stock more than 60 days",AC23<=60,"Out of stock less than 60 days",AC23>=150,"Out of stock more than 150 days") | AF23: =VLOOKUP(C23,'Data Products'!$A:$J,10,0) | AG23: =AF23*F23
A24: 21 | B24: Temporary | C24: CNMCU10GBFY15D | D24: CNMCU10GBFY15D | E24: CNMCU10GBFY15D | F24: 2000 | G24: 2000 | I24: =VLOOKUP(C24,'Data Products'!$A:$B,2,0) | J24: =IFERROR(I24-TODAY(),"") | K24: 45417 | L24: =TODAY()-K24 | M24: 0 | N24: 0 | AB24: =N24/30 | AC24: =IFERROR(F24/AB24,"-") | AD24: =IFERROR(TODAY()+AC24,"-") | AE24: =_xlfn.IFS(AC24="-","Not sold yet",AND(AC24<=150,AC24>60),"Out of stock more than 60 days",AC24<=60,"Out of stock less than 60 days",AC24>=150,"Out of stock more than 150 days") | AF24: =VLOOKUP(C24,'Data Products'!$A:$J,10,0) | AG24: =AF24*F24
AE25: Total stock with retail price | AF25: =AG25/$AG$25 | AG25: =SUM(AG4:AG24) | AH25: =SUM(AH4:AH24) | AI25: =SUM(AI4:AI24)
AE26: Out of stock less than 60 days | AF26: =AG26/$AG$25 | AG26: =SUMIFS($AG$4:$AG$24,$AE$4:$AE$24,$AE$26)
AE27: Not sold yet | AF27: =AG27/$AG$25 | AG27: =SUMIFS($AG$4:$AG$24,$AE$4:$AE$24,AE27)
AE28: Out of stock more than 60 days | AF28: =AG28/$AG$25 | AG28: =SUMIFS($AG$4:$AG$24,$AE$4:$AE$24,AE28)
AE29: Out of stock more than 150 days | AF29: =AG29/$AG$25 | AG29: =SUMIFS($AG$4:$AG$24,$AE$4:$AE$24,AE29)
AE30: Near Expiration Inventory | AF30: =AVERAGE(AE29:AC27)/AVERAGE(AE29:AC27) | AG30: =SUMIF($AC$4:$AC$24,"<90",AG4:AG24)
A32: ESIM VN | B32: Status | C32: SKU | D32: SKU (mới) | F32: Total Inventory | H32: Quantity | I32: Expiration | J32: Expired date left | K32: Date of Import | L32: Inventory Age | M32: Last 15 days | N32: Last 30 days | O32: Safety Stock | P32: Reorder Point | Q32: Vendor | AB32: Avg Pcs/day | AC32: DOI (Số ngày tồn kho) | AD32: Ngày hết hàng dự kiến | AE32: Đánh giá | AF32: Retail Price | AG32: Total retail price | AH32: Near Expiration Inventory | AI32: OPS | AJ32: Telco | AK32: OD | AL32: B2B | AM32: B2C | AN32: Marketing
A33: No. | F33: Stock | G33: Available for sale | M33: Sold | N33: Sold
A34: 1 | B34: Inactive | C34: 3HKDATAPOOLESIM | F34: 0 | G34: 0 | I34: =VLOOKUP(C34,'Data Products'!$A:$J,2,0) | J34: =IFERROR(I34-TODAY(),"") | K34: 45840 | L34: =TODAY()-K34 | M34: 0 | N34: 0 | Q34: 3HK | AB34: =N34/30 | AC34: =IFERROR(F34/AB34,"-") | AD34: =IFERROR(TODAY()+AC34,"-") | AE34: =_xlfn.IFS(AC34="-","Not sold yet",AND(AC34<=150,AC34>60),"Out of stock more than 60 days",AC34<=60,"Out of stock less than 60 days",AC34>=150,"Out of stock more than 150 days") | AF34: =VLOOKUP(C34,'Data Products'!$A:$J,10,0) | AG34: =AF34*F34 | AI34: treo chờ xử lý sau
A35: 2 | B35: Inactive | C35: EEURBGFX15GB15D | F35: 0 | G35: 0 | I35: =VLOOKUP(C35,'Data Products'!$A:$J,2,0) | J35: =IFERROR(I35-TODAY(),"") | K35: 45841 | L35: =TODAY()-K35 | M35: 0 | N35: 0 | Q35: Bouygues | AB35: =N35/30 | AC35: =IFERROR(F35/AB35,"-") | AD35: =IFERROR(TODAY()+AC35,"-") | AE35: =_xlfn.IFS(AC35="-","Not sold yet",AND(AC35<=150,AC35>60),"Out of stock more than 60 days",AC35<=60,"Out of stock less than 60 days",AC35>=150,"Out of stock more than 150 days") | AF35: =VLOOKUP(C35,'Data Products'!$A:$J,10,0) | AG35: =AF35*F35 | AH35: =IF(J35<=90,F35,0)
A36: 3 | B36: Inactive | C36: EEURBGFX20GB15D | F36: 0 | G36: 0 | I36: =VLOOKUP(C36,'Data Products'!$A:$J,2,0) | J36: =IFERROR(I36-TODAY(),"") | K36: 45842 | L36: =TODAY()-K36 | M36: 0 | N36: 0 | Q36: Bouygues | AB36: =N36/30 | AC36: =IFERROR(F36/AB36,"-") | AD36: =IFERROR(TODAY()+AC36,"-") | AE36: =_xlfn.IFS(AC36="-","Not sold yet",AND(AC36<=150,AC36>60),"Out of stock more than 60 days",AC36<=60,"Out of stock less than 60 days",AC36>=150,"Out of stock more than 150 days") | AF36: =VLOOKUP(C36,'Data Products'!$A:$J,10,0) | AG36: =AF36*F36 | AH36: =IF(J36<=90,F36,0)
A37: 4 | B37: Inactive | C37: EEURBGFX30GB30D | F37: 0 | G37: 0 | I37: =VLOOKUP(C37,'Data Products'!$A:$J,2,0) | J37: =IFERROR(I37-TODAY(),"") | K37: 45843 | L37: =TODAY()-K37 | M37: 0 | N37: 0 | Q37: Bouygues | AB37: =N37/30 | AC37: =IFERROR(F37/AB37,"-") | AD37: =IFERROR(TODAY()+AC37,"-") | AE37: =_xlfn.IFS(AC37="-","Not sold yet",AND(AC37<=150,AC37>60),"Out of stock more than 60 days",AC37<=60,"Out of stock less than 60 days",AC37>=150,"Out of stock more than 150 days") | AF37: =VLOOKUP(C37,'Data Products'!$A:$J,10,0) | AG37: =AF37*F37 | AH37: =IF(J37<=90,F37,0)
A38: 5 | B38: Deleted | C38: ECMTCUFY05GB05D | F38: 0 | G38: 0 | I38: =VLOOKUP(C38,'Data Products'!$A:$J,2,0) | J38: =IFERROR(I38-TODAY(),"") | K38: 45844 | L38: =TODAY()-K38 | M38: 0 | N38: 0 | Q38: CU | AB38: =N38/30 | AC38: =IFERROR(F38/AB38,"-") | AD38: =IFERROR(TODAY()+AC38,"-") | AE38: =_xlfn.IFS(AC38="-","Not sold yet",AND(AC38<=150,AC38>60),"Out of stock more than 60 days",AC38<=60,"Out of stock less than 60 days",AC38>=150,"Out of stock more than 150 days") | AF38: =VLOOKUP(C38,'Data Products'!$A:$J,10,0) | AG38: =AF38*F38 | AH38: =IF(J38<=90,F38,0) | AK38: 200
A39: 6 | B39: Temporary | C39: ECNMCUFX15GB30D | D39: 1CCNMCUY01530 | F39: 0 | G39: 0 | I39: =VLOOKUP(C39,'Data Products'!$A:$J,2,0) | J39: =IFERROR(I39-TODAY(),"") | K39: 45845 | L39: =TODAY()-K39 | M39: 0 | N39: 0 | Q39: CU | AB39: =N39/30 | AC39: =IFERROR(F39/AB39,"-") | AD39: =IFERROR(TODAY()+AC39,"-") | AE39: =_xlfn.IFS(AC39="-","Not sold yet",AND(AC39<=150,AC39>60),"Out of stock more than 60 days",AC39<=60,"Out of stock less than 60 days",AC39>=150,"Out of stock more than 150 days") | AF39: =VLOOKUP(C39,'Data Products'!$A:$J,10,0) | AG39: =AF39*F39 | AH39: =IF(J39<=90,F39,0)
A40: 7 | B40: Temporary | C40: 1CKORCUF01005 | D40: 1CKORCUF01005 | F40: 0 | G40: 0 | I40: =VLOOKUP(C40,'Data Products'!$A:$J,2,0) | J40: =IFERROR(I40-TODAY(),"") | K40: 45846 | L40: =TODAY()-K40 | M40: 0 | N40: 0 | Q40: CU | AB40: =N40/30 | AC40: =IFERROR(F40/AB40,"-") | AD40: =IFERROR(TODAY()+AC40,"-") | AE40: =_xlfn.IFS(AC40="-","Not sold yet",AND(AC40<=150,AC40>60),"Out of stock more than 60 days",AC40<=60,"Out of stock less than 60 days",AC40>=150,"Out of stock more than 150 days") | AF40: =VLOOKUP(C40,'Data Products'!$A:$J,10,0) | AG40: =AF40*F40 | AH40: =IF(J40<=90,F40,0)
A41: 8 | B41: Temporary | C41: EKORCUFY30GB30D | F41: 0 | G41: 0 | I41: =VLOOKUP(C41,'Data Products'!$A:$J,2,0) | J41: =IFERROR(I41-TODAY(),"") | K41: 45847 | L41: =TODAY()-K41 | M41: 0 | N41: 0 | Q41: CU | AB41: =N41/30 | AC41: =IFERROR(F41/AB41,"-") | AD41: =IFERROR(TODAY()+AC41,"-") | AE41: =_xlfn.IFS(AC41="-","Not sold yet",AND(AC41<=150,AC41>60),"Out of stock more than 60 days",AC41<=60,"Out of stock less than 60 days",AC41>=150,"Out of stock more than 150 days") | AF41: =VLOOKUP(C41,'Data Products'!$A:$J,10,0) | AG41: =AF41*F41 | AH41: =IF(J41<=90,F41,0)
...

Sheet 10.08
A1: SIM | B1: Status | C1: SKU (Sapo) | D1: SKU (mới) | E1: SKU (full) | F1: Total Inventory | H1: Quantity due to expiration | I1: Expiration | J1: Expired date left | K1: Date of Import | L1: Inventory Age | M1: Last 15 days | N1: Last 30 days | O1: Safety Stock (15D) | P1: Reorder Point (30D) | Q1: Vendor | R1: Kho tổng | T1: Phổ Quang - HCM | V1: Đống Đa - Hà Nội | X1: Tân Sơn Nhất - HCM | Z1: Chi nhánh Ký gửi | AB1: Avg Pcs/day | AC1: DOI (Số ngày tồn kho) | AD1: Estimated date out of stock | AE1: Evaluate | AF1: Retail Price | AG1: Total retail price | AH1: Near Expiration Inventory | AI1: OPS | AJ1: Telco | AK1: OD | AL1: WS | AM1: B2C | AN1: Marketing
A2: No. | F2: Stock | G2: Available for sale | M2: Sold | N2: Sold | R2: Stock | S2: Available for sale | T2: Stock | U2: Available for sale | V2: Stock | W2: Available for sale | X2: Stock | Y2: Available for sale | Z2: Stock | AA2: Available for sale
A3: 1 | B3: Temporary | C3: 3HKDATAPOOLSIM | D3: 3HKDATAPOOLSIM | E3: 1D0003DK00000 | F3: 419 | G3: 419 | I3: =VLOOKUP(C3,'Data Products'!$A:$B,2,0) | J3: =IFERROR(I3-TODAY(),"") | K3: 45723 | L3: =TODAY()-K3 | M3: 354 | N3: 380 | R3: 0 | S3: 0 | T3: 326 | U3: 326 | V3: 146 | W3: 146 | X3: 0 | Y3: 0 | Z3: 0 | AA3: 0 | AB3: =N3/30 | AC3: =IFERROR(F3/AB3,"-") | AD3: =IFERROR(TODAY()+AC3,"-") | AE3: =_xlfn.IFS(AC3="-","Not sold yet",AND(AC3<=150,AC3>60),"Out of stock more than 60 days",AC3<=60,"Out of stock less than 60 days",AC3>=150,"Out of stock more than 150 days") | AF3: =VLOOKUP(C3,'Data Products'!$A:$J,10,0) | AG3: =AF3*F3 | AH3: =IF(J3<=90,F3,0) | AI3: =IFERROR(VLOOKUP(C3,$C$3:$AI$42,34,0),"")
A4: 1 | B4: Active | C4: 1D0003DK00000 | D4: 1D0003DK00000 | E4: 1D0003DK00000 | F4: 18479 | G4: 18407 | I4: =VLOOKUP(C4,'Data Products'!$A:$B,2,0) | J4: =IFERROR(I4-TODAY(),"") | K4: 45617 | L4: =TODAY()-K4 | M4: 9349 | N4: 15283 | R4: 0 | S4: 0 | T4: 1378 | U4: 1369 | V4: 115 | W4: 112 | X4: 46 | Y4: 22 | Z4: 0 | AA4: 0 | AB4: =N4/30 | AC4: =IFERROR(F4/AB4,"-") | AD4: =IFERROR(TODAY()+AC4,"-") | AE4: =_xlfn.IFS(AC4="-","Not sold yet",AND(AC4<=150,AC4>60),"Out of stock more than 60 days",AC4<=60,"Out of stock less than 60 days",AC4>=150,"Out of stock more than 150 days") | AF4: =VLOOKUP(C4,'Data Products'!$A:$J,10,0) | AG4: =AF4*F4 | AH4: =IF(J4<=90,F4,0) | AI4: cần có hàng mới 20 - 25/08 để an toàn
A5: 2 | B5: Active | C5: 1D000BCK00000 | D5: 1D000BCK00000 | E5: 1D000BCK00000 | F5: 285 | G5: 285 | I5: =VLOOKUP(C5,'Data Products'!$A:$B,2,0) | J5: =IFERROR(I5-TODAY(),"") | K5: 45191 | L5: =TODAY()-K5 | M5: 17 | N5: 36 | R5: 0 | S5: 0 | T5: 26 | U5: 26 | V5: 416 | W5: 416 | X5: 0 | Y5: 0 | Z5: 0 | AA5: 0 | AB5: =N5/30 | AC5: =IFERROR(F5/AB5,"-") | AD5: =IFERROR(TODAY()+AC5,"-") | AE5: =_xlfn.IFS(AC5="-","Not sold yet",AND(AC5<=150,AC5>60),"Out of stock more than 60 days",AC5<=60,"Out of stock less than 60 days",AC5>=150,"Out of stock more than 150 days") | AF5: =VLOOKUP(C5,'Data Products'!$A:$J,10,0) | AG5: =AF5*F5 | AH5: =IF(J5<=90,F5,0) | AI5: sắp hết hạn, gia hạn thêm 1 tháng
A6: 3 | B6: Active | C6: 1D000ELK00000 | D6: 1D000ELK00000 | E6: 1D000ELK00000 | F6: 4268 | G6: 4268 | I6: =VLOOKUP(C6,'Data Products'!$A:$B,2,0) | J6: =IFERROR(I6-TODAY(),"") | K6: 45752 | L6: =TODAY()-K6 | M6: 28 | N6: 48 | R6: 0 | S6: 0 | T6: 1 | U6: 1 | V6: 1 | W6: 1 | X6: 0 | Y6: 0 | Z6: 0 | AA6: 0 | AB6: =N6/30 | AC6: =IFERROR(F6/AB6,"-") | AD6: =IFERROR(TODAY()+AC6,"-") | AE6: =_xlfn.IFS(AC6="-","Not sold yet",AND(AC6<=150,AC6>60),"Out of stock more than 60 days",AC6<=60,"Out of stock less than 60 days",AC6>=150,"Out of stock more than 150 days") | AF6: =VLOOKUP(C6,'Data Products'!$A:$J,10,0) | AG6: =AF6*F6 | AH6: =IF(J6<=90,F6,0) | AI6: =IFERROR(VLOOKUP(C6,$C$3:$AI$42,34,0),"")
A7: 4 | B7: Active | C7: 1D000JYK00000 | D7: 1D000JYK00000 | E7: 1D000JYK00000 | F7: 882 | G7: 862 | I7: =VLOOKUP(C7,'Data Products'!$A:$B,2,0) | J7: =IFERROR(I7-TODAY(),"") | K7: 45854 | L7: =TODAY()-K7 | M7: 3 | N7: 6 | R7: 0 | S7: 0 | T7: 288 | U7: 288 | V7: 512 | W7: 512 | X7: 20 | Y7: 20 | Z7: 0 | AA7: 0 | AB7: =N7/30 | AC7: =IFERROR(F7/AB7,"-") | AD7: =IFERROR(TODAY()+AC7,"-") | AE7: =_xlfn.IFS(AC7="-","Not sold yet",AND(AC7<=150,AC7>60),"Out of stock more than 60 days",AC7<=60,"Out of stock less than 60 days",AC7>=150,"Out of stock more than 150 days") | AF7: =VLOOKUP(C7,'Data Products'!$A:$J,10,0) | AG7: =AF7*F7 | AH7: =IF(J7<=90,F7,0) | AI7: =IFERROR(VLOOKUP(C7,$C$3:$AI$42,34,0),"")
A8: 5 | B8: Active | C8: 1D000SSK00000 | D8: 1D000SSK00000 | E8: 1D000SSK00000 | F8: 2468 | G8: 2468 | I8: =VLOOKUP(C8,'Data Products'!$A:$B,2,0) | J8: =IFERROR(I8-TODAY(),"") | K8: 45855 | L8: =TODAY()-K8 | M8: 9 | N8: 52 | R8: 0 | S8: 0 | T8: 51 | U8: 51 | V8: 101 | W8: 101 | X8: 0 | Y8: 0 | Z8: 0 | AA8: 0 | AB8: =N8/30 | AC8: =IFERROR(F8/AB8,"-") | AD8: =IFERROR(TODAY()+AC8,"-") | AE8: =_xlfn.IFS(AC8="-","Not sold yet",AND(AC8<=150,AC8>60),"Out of stock more than 60 days",AC8<=60,"Out of stock less than 60 days",AC8>=150,"Out of stock more than 150 days") | AF8: =VLOOKUP(C8,'Data Products'!$A:$J,10,0) | AG8: =AF8*F8 | AH8: =IF(J8<=90,F8,0) | AI8: =IFERROR(VLOOKUP(C8,$C$3:$AI$42,34,0)," ")
A9: 6 | B9: Active | C9: 1D000UBK00000 | D9: 1D000UBK00000 | E9: 1D000UBK00000 | F9: 2062 | G9: 2062 | I9: =VLOOKUP(C9,'Data Products'!$A:$B,2,0) | J9: =IFERROR(I9-TODAY(),"") | K9: 45856 | L9: =TODAY()-K9 | M9: 0 | N9: 0 | R9: 0 | S9: 0 | T9: 1480 | U9: 1478 | V9: 1112 | W9: 1112 | X9: 0 | Y9: 0 | Z9: 0 | AA9: 0 | AB9: =N9/30 | AC9: =IFERROR(F9/AB9,"-") | AD9: =IFERROR(TODAY()+AC9,"-") | AE9: =_xlfn.IFS(AC9="-","Not sold yet",AND(AC9<=150,AC9>60),"Out of stock more than 60 days",AC9<=60,"Out of stock less than 60 days",AC9>=150,"Out of stock more than 150 days") | AF9: =VLOOKUP(C9,'Data Products'!$A:$J,10,0) | AG9: =AF9*F9 | AH9: =IF(J9<=90,F9,0) | AI9: =IFERROR(VLOOKUP(C9,$C$3:$AI$42,34,0),"")
A10: 7 | B10: Active | C10: 1D000WMK00000 | D10: 1D000WMK00000 | E10: 1D000WMK00000 | F10: 461 | G10: 458 | I10: =VLOOKUP(C10,'Data Products'!$A:$B,2,0) | J10: =IFERROR(I10-TODAY(),"") | K10: 45857 | L10: =TODAY()-K10 | M10: 132 | N10: 267 | R10: 0 | S10: 0 | T10: 0 | U10: 0 | V10: 2 | W10: 2 | X10: 0 | Y10: 0 | Z10: 0 | AA10: 0 | AB10: =N10/30 | AC10: =IFERROR(F10/AB10,"-") | AD10: =IFERROR(TODAY()+AC10,"-") | AE10: =_xlfn.IFS(AC10="-","Not sold yet",AND(AC10<=150,AC10>60),"Out of stock more than 60 days",AC10<=60,"Out of stock less than 60 days",AC10>=150,"Out of stock more than 150 days") | AF10: =VLOOKUP(C10,'Data Products'!$A:$J,10,0) | AG10: =AF10*F10 | AH10: =IF(J10<=90,F10,0) | AI10: =IFERROR(VLOOKUP(C10,$C$3:$AI$42,34,0),"")
A11: 8 | B11: Temporary | C11: CNMCU05GBFY05D | D11: CNMCU05GBFY05D | E11: CNMCU05GBFY05D | F11: 1200 | G11: 1200 | I11: =VLOOKUP(C11,'Data Products'!$A:$B,2,0) | J11: =IFERROR(I11-TODAY(),"") | K11: 45858 | L11: =TODAY()-K11 | M11: 0 | N11: 0 | R11: 0 | S11: 0 | T11: 1289 | U11: 1289 | V11: 773 | W11: 773 | X11: 0 | Y11: 0 | Z11: 0 | AA11: 0 | AB11: =N11/30 | AC11: =IFERROR(F11/AB11,"-") | AD11: =IFERROR(TODAY()+AC11,"-") | AE11: =_xlfn.IFS(AC11="-","Not sold yet",AND(AC11<=150,AC11>60),"Out of stock more than 60 days",AC11<=60,"Out of stock less than 60 days",AC11>=150,"Out of stock more than 150 days") | AF11: =VLOOKUP(C11,'Data Products'!$A:$J,10,0) | AG11: =AF11*F11 | AH11: =IF(J11<=90,F11,0) | AI11: =IFERROR(VLOOKUP(C11,$C$3:$AI$42,34,0),"")
A12: 9 | B12: Temporary | C12: CNMCU07GBFY08D | D12: CNMCU07GBFY08D | E12: CNMCU07GBFY08D | F12: 1000 | G12: 1000 | I12: =VLOOKUP(C12,'Data Products'!$A:$B,2,0) | J12: =IFERROR(I12-TODAY(),"") | K12: 45532 | L12: =TODAY()-K12 | M12: 0 | N12: 0 | R12: 0 | S12: 0 | T12: 417 | U12: 416 | V12: 785 | W12: 785 | X12: 0 | Y12: 0 | Z12: 0 | AA12: 0 | AB12: =N12/30 | AC12: =IFERROR(F12/AB12,"-") | AD12: =IFERROR(TODAY()+AC12,"-") | AE12: =_xlfn.IFS(AC12="-","Not sold yet",AND(AC12<=150,AC12>60),"Out of stock more than 60 days",AC12<=60,"Out of stock less than 60 days",AC12>=150,"Out of stock more than 150 days") | AF12: =VLOOKUP(C12,'Data Products'!$A:$J,10,0) | AG12: =AF12*F12 | AH12: =IF(J12<=90,F12,0) | AI12: qua tết push lại, mỗi tuần nhắc lại
A13: 10 | B13: Temporary | C13: KORCU10GBFY05D | D13: KORCU10GBFY05D | E13: KORCU10GBFY05D | F13: 500 | G13: 500 | I13: =VLOOKUP(C13,'Data Products'!$A:$B,2,0) | J13: =IFERROR(I13-TODAY(),"") | K13: 45504 | L13: =TODAY()-K13 | M13: 0 | N13: 0 | R13: 0 | S13: 0 | T13: 3870 | U13: 1017 | V13: 366 | W13: 366 | X13: 0 | Y13: 0 | Z13: 0 | AA13: 0 | AB13: =N13/30 | AC13: =IFERROR(F13/AB13,"-") | AD13: =IFERROR(TODAY()+AC13,"-") | AE13: =_xlfn.IFS(AC13="-","Not sold yet",AND(AC13<=150,AC13>60),"Out of stock more than 60 days",AC13<=60,"Out of stock less than 60 days",AC13>=150,"Out of stock more than 150 days") | AF13: =VLOOKUP(C13,'Data Products'!$A:$J,10,0) | AG13: =AF13*F13 | AH13: =IF(J13<=90,F13,0) | AI13: =IFERROR(VLOOKUP(C13,$C$3:$AI$42,34,0),"")
A14: 11 | B14: Active | C14: 1DCNMCTF00705 | D14: 1DCNMCTF00705 | E14: 1ECNMCTF00705 | F14: 181 | G14: 181 | I14: =VLOOKUP(C14,'Data Products'!$A:$B,2,0) | J14: =IFERROR(I14-TODAY(),"") | K14: 45504 | L14: =TODAY()-K14 | M14: 1 | N14: 1 | R14: 1200 | S14: 1200 | T14: 0 | U14: 0 | V14: 0 | W14: 0 | X14: 0 | Y14: 0 | Z14: 0 | AA14: 0 | AB14: =N14/30 | AC14: =IFERROR(F14/AB14,"-") | AD14: =IFERROR(TODAY()+AC14,"-") | AE14: =_xlfn.IFS(AC14="-","Not sold yet",AND(AC14<=150,AC14>60),"Out of stock more than 60 days",AC14<=60,"Out of stock less than 60 days",AC14>=150,"Out of stock more than 150 days") | AF14: =VLOOKUP(C14,'Data Products'!$A:$J,10,0) | AG14: =AF14*F14 | AH14: =IF(J14<=90,F14,0) | AI14: =IFERROR(VLOOKUP(C14,$C$3:$AI$42,34,0)," ")
A15: 12 | B15: Active | C15: 1DCNMCUF01530 | D15: 1DCNMCUF01530 | E15: 1ECNMCUF01530 | F15: 98 | G15: 98 | I15: =VLOOKUP(C15,'Data Products'!$A:$B,2,0) | J15: =IFERROR(I15-TODAY(),"") | K15: 45648 | L15: =TODAY()-K15 | M15: 4 | N15: 7 | R15: 1000 | S15: 1000 | T15: 0 | U15: 0 | V15: 0 | W15: 0 | X15: 0 | Y15: 0 | Z15: 0 | AA15: 0 | AB15: =N15/30 | AC15: =IFERROR(F15/AB15,"-") | AD15: =IFERROR(TODAY()+AC15,"-") | AE15: =_xlfn.IFS(AC15="-","Not sold yet",AND(AC15<=150,AC15>60),"Out of stock more than 60 days",AC15<=60,"Out of stock less than 60 days",AC15>=150,"Out of stock more than 150 days") | AF15: =VLOOKUP(C15,'Data Products'!$A:$J,10,0) | AG15: =AF15*F15 | AH15: =IF(J15<=90,F15,0) | AI15: =IFERROR(VLOOKUP(C15,$C$3:$AI$42,34,0),"")
A16: 13 | B16: Active | C16: 1DCNMCUF00303 | D16: 1DCNMCUF00303 | E16: 1ECNMCUF00303 | F16: 846 | G16: 846 | I16: =VLOOKUP(C16,'Data Products'!$A:$B,2,0) | J16: =IFERROR(I16-TODAY(),"") | K16: 45504 | L16: =TODAY()-K16 | M16: 101 | N16: 103 | R16: 500 | S16: 500 | T16: 0 | U16: 0 | V16: 0 | W16: 0 | X16: 0 | Y16: 0 | Z16: 0 | AA16: 0 | AB16: =N16/30 | AC16: =IFERROR(F16/AB16,"-") | AD16: =IFERROR(TODAY()+AC16,"-") | AE16: =_xlfn.IFS(AC16="-","Not sold yet",AND(AC16<=150,AC16>60),"Out of stock more than 60 days",AC16<=60,"Out of stock less than 60 days",AC16>=150,"Out of stock more than 150 days") | AF16: =VLOOKUP(C16,'Data Products'!$A:$J,10,0) | AG16: =AF16*F16 | AH16: =IF(J16<=90,F16,0) | AI16: =IFERROR(VLOOKUP(C16,$C$3:$AI$42,34,0),"")
A17: 14 | B17: Active | C17: 1DCNMCUF00505 | D17: 1DCNMCUF00505 | E17: 1ECNMCUF00505 | F17: 0 | G17: 0 | I17: =VLOOKUP(C17,'Data Products'!$A:$B,2,0) | J17: =IFERROR(I17-TODAY(),"") | K17: 45653 | L17: =TODAY()-K17 | M17: 0 | N17: 0 | R17: 0 | S17: 0 | T17: 128 | U17: 128 | V17: 54 | W17: 54 | X17: 0 | Y17: 0 | Z17: 0 | AA17: 0 | AB17: =N17/30 | AC17: =IFERROR(F17/AB17,"-") | AD17: =IFERROR(TODAY()+AC17,"-") | AE17: =_xlfn.IFS(AC17="-","Not sold yet",AND(AC17<=150,AC17>60),"Out of stock more than 60 days",AC17<=60,"Out of stock less than 60 days",AC17>=150,"Out of stock more than 150 days") | AF17: =VLOOKUP(C17,'Data Products'!$A:$J,10,0) | AG17: =AF17*F17 | AH17: =IF(J17<=90,F17,0) | AI17: =IFERROR(VLOOKUP(C17,$C$3:$AI$42,34,0),"")
A18: 15 | B18: Active | C18: 1DTHADTF05010 | D18: 1DTHADTF05010 | E18: 1ETHADTF05010 | F18: 5 | G18: 5 | I18: =VLOOKUP(C18,'Data Products'!$A:$B,2,0) | J18: =IFERROR(I18-TODAY(),"") | K18: 45737 | L18: =TODAY()-K18 | M18: 0 | N18: 0 | R18: 0 | S18: 0 | T18: 0 | U18: 0 | V18: 116 | W18: 116 | X18: 0 | Y18: 0 | Z18: 0 | AA18: 0 | AB18: =N18/30 | AC18: =IFERROR(F18/AB18,"-") | AD18: =IFERROR(TODAY()+AC18,"-") | AE18: =_xlfn.IFS(AC18="-","Not sold yet",AND(AC18<=150,AC18>60),"Out of stock more than 60 days",AC18<=60,"Out of stock less than 60 days",AC18>=150,"Out of stock more than 150 days") | AF18: =VLOOKUP(C18,'Data Products'!$A:$J,10,0) | AG18: =AF18*F18 | AH18: =IF(J18<=90,F18,0)
A19: 16 | B19: Active | C19: 1DWORCBF01030 | D19: 1DWORCBF01030 | E19: 1DWORCBF01030 | F19: 323 | G19: 323 | I19: =VLOOKUP(C19,'Data Products'!$A:$B,2,0) | J19: =IFERROR(I19-TODAY(),"") | K19: 45653 | L19: =TODAY()-K19 | M19: 0 | N19: 113 | R19: 600 | S19: 600 | T19: 100 | U19: 100 | V19: 300 | W19: 300 | X19: 0 | Y19: 0 | Z19: 0 | AA19: 0 | AB19: =N19/30 | AC19: =IFERROR(F19/AB19,"-") | AD19: =IFERROR(TODAY()+AC19,"-") | AE19: =_xlfn.IFS(AC19="-","Not sold yet",AND(AC19<=150,AC19>60),"Out of stock more than 60 days",AC19<=60,"Out of stock less than 60 days",AC19>=150,"Out of stock more than 150 days") | AF19: =VLOOKUP(C19,'Data Products'!$A:$J,10,0) | AG19: =AF19*F19 | AH19: =IF(J19<=90,F19,0)
A20: 17 | B20: Active | C20: 1DTHATMF01507 | D20: 1DTHATMF01507 | E20: 1ETHATMF01507 | F20: 3984 | G20: 3977 | I20: =VLOOKUP(C20,'Data Products'!$A:$B,2,0) | J20: =IFERROR(I20-TODAY(),"") | K20: 45653 | L20: =TODAY()-K20 | M20: 738 | N20: 3090 | R20: 0 | S20: 0 | T20: 27 | U20: 27 | V20: 25 | W20: 25 | X20: 0 | Y20: 0 | Z20: 0 | AA20: 0 | AB20: =N20/30 | AC20: =IFERROR(F20/AB20,"-") | AD20: =IFERROR(TODAY()+AC20,"-") | AE20: =_xlfn.IFS(AC20="-","Not sold yet",AND(AC20<=150,AC20>60),"Out of stock more than 60 days",AC20<=60,"Out of stock less than 60 days",AC20>=150,"Out of stock more than 150 days") | AF20: =VLOOKUP(C20,'Data Products'!$A:$J,10,0) | AG20: =AF20*F20 | AH20: =IF(J20<=90,F20,0) | AI20: cần đầu tháng 9 có hàng mới
A21: 18 | B21: Active | C21: 1DTHATMF05010 | D21: 1DTHATMF05010 | E21: 1ETHATMF05010 | F21: 7590 | G21: 7581 | I21: =VLOOKUP(C21,'Data Products'!$A:$B,2,0) | J21: =IFERROR(I21-TODAY(),"") | K21: 45847 | L21: =TODAY()-K21 | M21: 518 | N21: 811 | R21: 0 | S21: 0 | T21: 113 | U21: 106 | V21: 1097 | W21: 1097 | X21: 5 | Y21: 0 | Z21: 0 | AA21: 0 | AB21: =N21/30 | AC21: =IFERROR(F21/AB21,"-") | AD21: =IFERROR(TODAY()+AC21,"-") | AE21: =_xlfn.IFS(AC21="-","Not sold yet",AND(AC21<=150,AC21>60),"Out of stock more than 60 days",AC21<=60,"Out of stock less than 60 days",AC21>=150,"Out of stock more than 150 days") | AF21: =VLOOKUP(C21,'Data Products'!$A:$J,10,0) | AG21: =AF21*F21 | AH21: =IF(J21<=90,F21,0) | AI21: cần đầu tháng 9 có hàng mới
A22: 19 | B22: Active | C22: 1DTHATMF01507 | D22: 1DTHATMF01507 | E22: 1ETHATMF01507 | F22: 3984 | G22: 3977 | I22: =VLOOKUP(C22,'Data Products'!$A:$B,2,0) | J22: =IFERROR(I22-TODAY(),"") | K22: 45847 | L22: =TODAY()-K22 | M22: 738 | N22: 3090 | R22: 0 | S22: 0 | T22: 154 | U22: 154 | V22: 310 | W22: 310 | X22: 0 | Y22: 0 | Z22: 0 | AA22: 0 | AB22: =N22/30 | AC22: =IFERROR(F22/AB22,"-") | AD22: =IFERROR(TODAY()+AC22,"-") | AE22: =_xlfn.IFS(AC22="-","Not sold yet",AND(AC22<=150,AC22>60),"Out of stock more than 60 days",AC22<=60,"Out of stock less than 60 days",AC22>=150,"Out of stock more than 150 days") | AF22: =VLOOKUP(C22,'Data Products'!$A:$J,10,0) | AG22: =AF22*F22 | AH22: =IF(J22<=90,F22,0) | AI22: pass quý 1 push lại
A23: 20 | B23: Temporary | C23: CNMCU15GBFY30D | D23: CNMCU15GBFY30D | E23: CNMCU15GBFY30D | F23: 1500 | G23: 1500 | I23: =VLOOKUP(C23,'Data Products'!$A:$B,2,0) | J23: =IFERROR(I23-TODAY(),"") | K23: 45416 | L23: =TODAY()-K23 | M23: 0 | N23: 0 | AB23: =N23/30 | AC23: =IFERROR(F23/AB23,"-") | AD23: =IFERROR(TODAY()+AC23,"-") | AE23: =_xlfn.IFS(AC23="-","Not sold yet",AND(AC23<=150,AC23>60),"Out of stock more than 60 days",AC23<=60,"Out of stock less than 60 days",AC23>=150,"Out of stock more than 150 days") | AF23: =VLOOKUP(C23,'Data Products'!$A:$J,10,0) | AG23: =AF23*F23
A24: 21 | B24: Temporary | C24: CNMCU10GBFY15D | D24: CNMCU10GBFY15D | E24: CNMCU10GBFY15D | F24: 2000 | G24: 2000 | I24: =VLOOKUP(C24,'Data Products'!$A:$B,2,0) | J24: =IFERROR(I24-TODAY(),"") | K24: 45417 | L24: =TODAY()-K24 | M24: 0 | N24: 0 | AB24: =N24/30 | AC24: =IFERROR(F24/AB24,"-") | AD24: =IFERROR(TODAY()+AC24,"-") | AE24: =_xlfn.IFS(AC24="-","Not sold yet",AND(AC24<=150,AC24>60),"Out of stock more than 60 days",AC24<=60,"Out of stock less than 60 days",AC24>=150,"Out of stock more than 150 days") | AF24: =VLOOKUP(C24,'Data Products'!$A:$J,10,0) | AG24: =AF24*F24
AE25: Total stock with retail price | AF25: =AG25/$AG$25 | AG25: =SUM(AG4:AG24) | AH25: =SUM(AH4:AH24) | AI25: =SUM(AI4:AI24)
AE26: Out of stock less than 60 days | AF26: =AG26/$AG$25 | AG26: =SUMIFS($AG$4:$AG$24,$AE$4:$AE$24,$AE$26)
AE27: Not sold yet | AF27: =AG27/$AG$25 | AG27: =SUMIFS($AG$4:$AG$24,$AE$4:$AE$24,AE27)
AE28: Out of stock more than 60 days | AF28: =AG28/$AG$25 | AG28: =SUMIFS($AG$4:$AG$24,$AE$4:$AE$24,AE28)
AE29: Out of stock more than 150 days | AF29: =AG29/$AG$25 | AG29: =SUMIFS($AG$4:$AG$24,$AE$4:$AE$24,AE29)
AE30: Near Expiration Inventory | AF30: =AVERAGE(AE29:AC27)/AVERAGE(AE29:AC27) | AG30: =SUMIF($AC$4:$AC$24,"<90",AG4:AG24)
A32: ESIM VN | B32: Status | C32: SKU | D32: SKU (mới) | F32: Total Inventory | H32: Quantity | I32: Expiration | J32: Expired date left | K32: Date of Import | L32: Inventory Age | M32: Last 15 days | N32: Last 30 days | O32: Safety Stock | P32: Reorder Point | Q32: Vendor | AB32: Avg Pcs/day | AC32: DOI (Số ngày tồn kho) | AD32: Ngày hết hàng dự kiến | AE32: Đánh giá | AF32: Retail Price | AG32: Total retail price | AH32: Near Expiration Inventory | AI32: OPS | AJ32: Telco | AK32: OD | AL32: B2B | AM32: B2C | AN32: Marketing
A33: No. | F33: Stock | G33: Available for sale | M33: Sold | N33: Sold
A34: 1 | B34: Inactive | C34: 3HKDATAPOOLESIM | F34: 0 | G34: 0 | I34: =VLOOKUP(C34,'Data Products'!$A:$J,2,0) | J34: =IFERROR(I34-TODAY(),"") | K34: 45840 | L34: =TODAY()-K34 | M34: 0 | N34: 0 | Q34: 3HK | AB34: =N34/30 | AC34: =IFERROR(F34/AB34,"-") | AD34: =IFERROR(TODAY()+AC34,"-") | AE34: =_xlfn.IFS(AC34="-","Not sold yet",AND(AC34<=150,AC34>60),"Out of stock more than 60 days",AC34<=60,"Out of stock less than 60 days",AC34>=150,"Out of stock more than 150 days") | AF34: =VLOOKUP(C34,'Data Products'!$A:$J,10,0) | AG34: =AF34*F34 | AI34: treo chờ xử lý sau
A35: 2 | B35: Inactive | C35: EEURBGFX15GB15D | F35: 0 | G35: 0 | I35: =VLOOKUP(C35,'Data Products'!$A:$J,2,0) | J35: =IFERROR(I35-TODAY(),"") | K35: 45841 | L35: =TODAY()-K35 | M35: 0 | N35: 0 | Q35: Bouygues | AB35: =N35/30 | AC35: =IFERROR(F35/AB35,"-") | AD35: =IFERROR(TODAY()+AC35,"-") | AE35: =_xlfn.IFS(AC35="-","Not sold yet",AND(AC35<=150,AC35>60),"Out of stock more than 60 days",AC35<=60,"Out of stock less than 60 days",AC35>=150,"Out of stock more than 150 days") | AF35: =VLOOKUP(C35,'Data Products'!$A:$J,10,0) | AG35: =AF35*F35 | AH35: =IF(J35<=90,F35,0)
A36: 3 | B36: Inactive | C36: EEURBGFX20GB15D | F36: 0 | G36: 0 | I36: =VLOOKUP(C36,'Data Products'!$A:$J,2,0) | J36: =IFERROR(I36-TODAY(),"") | K36: 45842 | L36: =TODAY()-K36 | M36: 0 | N36: 0 | Q36: Bouygues | AB36: =N36/30 | AC36: =IFERROR(F36/AB36,"-") | AD36: =IFERROR(TODAY()+AC36,"-") | AE36: =_xlfn.IFS(AC36="-","Not sold yet",AND(AC36<=150,AC36>60),"Out of stock more than 60 days",AC36<=60,"Out of stock less than 60 days",AC36>=150,"Out of stock more than 150 days") | AF36: =VLOOKUP(C36,'Data Products'!$A:$J,10,0) | AG36: =AF36*F36 | AH36: =IF(J36<=90,F36,0)
A37: 4 | B37: Inactive | C37: EEURBGFX30GB30D | F37: 0 | G37: 0 | I37: =VLOOKUP(C37,'Data Products'!$A:$J,2,0) | J37: =IFERROR(I37-TODAY(),"") | K37: 45843 | L37: =TODAY()-K37 | M37: 0 | N37: 0 | Q37: Bouygues | AB37: =N37/30 | AC37: =IFERROR(F37/AB37,"-") | AD37: =IFERROR(TODAY()+AC37,"-") | AE37: =_xlfn.IFS(AC37="-","Not sold yet",AND(AC37<=150,AC37>60),"Out of stock more than 60 days",AC37<=60,"Out of stock less than 60 days",AC37>=150,"Out of stock more than 150 days") | AF37: =VLOOKUP(C37,'Data Products'!$A:$J,10,0) | AG37: =AF37*F37 | AH37: =IF(J37<=90,F37,0)
A38: 5 | B38: Deleted | C38: ECMTCUFY05GB05D | F38: 0 | G38: 0 | I38: =VLOOKUP(C38,'Data Products'!$A:$J,2,0) | J38: =IFERROR(I38-TODAY(),"") | K38: 45844 | L38: =TODAY()-K38 | M38: 0 | N38: 0 | Q38: CU | AB38: =N38/30 | AC38: =IFERROR(F38/AB38,"-") | AD38: =IFERROR(TODAY()+AC38,"-") | AE38: =_xlfn.IFS(AC38="-","Not sold yet",AND(AC38<=150,AC38>60),"Out of stock more than 60 days",AC38<=60,"Out of stock less than 60 days",AC38>=150,"Out of stock more than 150 days") | AF38: =VLOOKUP(C38,'Data Products'!$A:$J,10,0) | AG38: =AF38*F38 | AH38: =IF(J38<=90,F38,0) | AK38: 200
A39: 6 | B39: Temporary | C39: ECNMCUFX15GB30D | D39: 1CCNMCUY01530 | F39: 0 | G39: 0 | I39: =VLOOKUP(C39,'Data Products'!$A:$J,2,0) | J39: =IFERROR(I39-TODAY(),"") | K39: 45845 | L39: =TODAY()-K39 | M39: 0 | N39: 0 | Q39: CU | AB39: =N39/30 | AC39: =IFERROR(F39/AB39,"-") | AD39: =IFERROR(TODAY()+AC39,"-") | AE39: =_xlfn.IFS(AC39="-","Not sold yet",AND(AC39<=150,AC39>60),"Out of stock more than 60 days",AC39<=60,"Out of stock less than 60 days",AC39>=150,"Out of stock more than 150 days") | AF39: =VLOOKUP(C39,'Data Products'!$A:$J,10,0) | AG39: =AF39*F39 | AH39: =IF(J39<=90,F39,0)
A40: 7 | B40: Temporary | C40: 1CKORCUF01005 | D40: 1CKORCUF01005 | F40: 0 | G40: 0 | I40: =VLOOKUP(C40,'Data Products'!$A:$J,2,0) | J40: =IFERROR(I40-TODAY(),"") | K40: 45846 | L40: =TODAY()-K40 | M40: 0 | N40: 0 | Q40: CU | AB40: =N40/30 | AC40: =IFERROR(F40/AB40,"-") | AD40: =IFERROR(TODAY()+AC40,"-") | AE40: =_xlfn.IFS(AC40="-","Not sold yet",AND(AC40<=150,AC40>60),"Out of stock more than 60 days",AC40<=60,"Out of stock less than 60 days",AC40>=150,"Out of stock more than 150 days") | AF40: =VLOOKUP(C40,'Data Products'!$A:$J,10,0) | AG40: =AF40*F40 | AH40: =IF(J40<=90,F40,0)
A41: 8 | B41: Temporary | C41: EKORCUFY30GB30D | F41: 0 | G41: 0 | I41: =VLOOKUP(C41,'Data Products'!$A:$J,2,0) | J41: =IFERROR(I41-TODAY(),"") | K41: 45847 | L41: =TODAY()-K41 | M41: 0 | N41: 0 | Q41: CU | AB41: =N41/30 | AC41: =IFERROR(F41/AB41,"-") | AD41: =IFERROR(TODAY()+AC41,"-") | AE41: =_xlfn.IFS(AC41="-","Not sold yet",AND(AC41<=150,AC41>60),"Out of stock more than 60 days",AC41<=60,"Out of stock less than 60 days",AC41>=150,"Out of stock more than 150 days") | AF41: =VLOOKUP(C41,'Data Products'!$A:$J,10,0) | AG41: =AF41*F41 | AH41: =IF(J41<=90,F41,0)
...

Sheet 06.08
A1: SIM | B1: Status | C1: SKU (Sapo) | D1: SKU (mới) | E1: SKU (full) | F1: Total Inventory | H1: Quantity due to expiration | I1: Expiration | J1: Expired date left | K1: Date of Import | L1: Inventory Age | M1: Last 15 days | N1: Last 30 days | O1: Safety Stock (15D) | P1: Reorder Point (30D) | Q1: Vendor | R1: Kho tổng | T1: Phổ Quang - HCM | V1: Đống Đa - Hà Nội | X1: Tân Sơn Nhất - HCM | Z1: Chi nhánh Ký gửi | AB1: Avg Pcs/day | AC1: DOI (Số ngày tồn kho) | AD1: Estimated date out of stock | AE1: Evaluate | AF1: Retail Price | AG1: Total retail price | AH1: Near Expiration Inventory | AI1: OPS | AJ1: Telco | AK1: OD | AL1: WS | AM1: B2C | AN1: Marketing
A2: No. | F2: Stock | G2: Available for sale | M2: Sold | N2: Sold | R2: Stock | S2: Available for sale | T2: Stock | U2: Available for sale | V2: Stock | W2: Available for sale | X2: Stock | Y2: Available for sale | Z2: Stock | AA2: Available for sale
A3: 1 | B3: Temporary | C3: 3HKDATAPOOLSIM | D3: 3HKDATAPOOLSIM | E3: 1D0003DK00000 | F3: 419 | G3: 419 | I3: =VLOOKUP(C3,'Data Products'!$A:$B,2,0) | J3: =IFERROR(I3-TODAY(),"") | K3: 45723 | L3: =TODAY()-K3 | M3: 354 | N3: 380 | R3: 0 | S3: 0 | T3: 326 | U3: 326 | V3: 146 | W3: 146 | X3: 0 | Y3: 0 | Z3: 0 | AA3: 0 | AB3: =N3/30 | AC3: =IFERROR(F3/AB3,"-") | AD3: =IFERROR(TODAY()+AC3,"-") | AE3: =_xlfn.IFS(AC3="-","Not sold yet",AND(AC3<=150,AC3>60),"Out of stock more than 60 days",AC3<=60,"Out of stock less than 60 days",AC3>=150,"Out of stock more than 150 days") | AF3: =VLOOKUP(C3,'Data Products'!$A:$J,10,0) | AG3: =AF3*F3 | AH3: =IF(J3<=90,F3,0) | AI3: =IFERROR(VLOOKUP(C3,$C$3:$AI$42,34,0),"")
A4: 1 | B4: Active | C4: 1D0003DK00000 | D4: 1D0003DK00000 | E4: 1D0003DK00000 | F4: 19815 | G4: 19763 | I4: =VLOOKUP(C4,'Data Products'!$A:$B,2,0) | J4: =IFERROR(I4-TODAY(),"") | K4: 45617 | L4: =TODAY()-K4 | M4: 9349 | N4: 17027 | R4: 0 | S4: 0 | T4: 1378 | U4: 1369 | V4: 115 | W4: 112 | X4: 46 | Y4: 22 | Z4: 0 | AA4: 0 | AB4: =N4/30 | AC4: =IFERROR(F4/AB4,"-") | AD4: =IFERROR(TODAY()+AC4,"-") | AE4: =_xlfn.IFS(AC4="-","Not sold yet",AND(AC4<=150,AC4>60),"Out of stock more than 60 days",AC4<=60,"Out of stock less than 60 days",AC4>=150,"Out of stock more than 150 days") | AF4: =VLOOKUP(C4,'Data Products'!$A:$J,10,0) | AG4: =AF4*F4 | AH4: =IF(J4<=90,F4,0) | AI4: cần có hàng mới 20 - 25/08 để an toàn
A5: 2 | B5: Active | C5: 1D000BCK00000 | D5: 1D000BCK00000 | E5: 1D000BCK00000 | F5: 292 | G5: 292 | I5: =VLOOKUP(C5,'Data Products'!$A:$B,2,0) | J5: =IFERROR(I5-TODAY(),"") | K5: 45191 | L5: =TODAY()-K5 | M5: 17 | N5: 29 | R5: 0 | S5: 0 | T5: 26 | U5: 26 | V5: 416 | W5: 416 | X5: 0 | Y5: 0 | Z5: 0 | AA5: 0 | AB5: =N5/30 | AC5: =IFERROR(F5/AB5,"-") | AD5: =IFERROR(TODAY()+AC5,"-") | AE5: =_xlfn.IFS(AC5="-","Not sold yet",AND(AC5<=150,AC5>60),"Out of stock more than 60 days",AC5<=60,"Out of stock less than 60 days",AC5>=150,"Out of stock more than 150 days") | AF5: =VLOOKUP(C5,'Data Products'!$A:$J,10,0) | AG5: =AF5*F5 | AH5: =IF(J5<=90,F5,0) | AI5: sắp hết hạn, gia hạn thêm 1 tháng
A6: 3 | B6: Active | C6: 1D000ELK00000 | D6: 1D000ELK00000 | E6: 1D000ELK00000 | F6: 4268 | G6: 4268 | I6: =VLOOKUP(C6,'Data Products'!$A:$B,2,0) | J6: =IFERROR(I6-TODAY(),"") | K6: 45752 | L6: =TODAY()-K6 | M6: 28 | N6: 48 | R6: 0 | S6: 0 | T6: 1 | U6: 1 | V6: 1 | W6: 1 | X6: 0 | Y6: 0 | Z6: 0 | AA6: 0 | AB6: =N6/30 | AC6: =IFERROR(F6/AB6,"-") | AD6: =IFERROR(TODAY()+AC6,"-") | AE6: =_xlfn.IFS(AC6="-","Not sold yet",AND(AC6<=150,AC6>60),"Out of stock more than 60 days",AC6<=60,"Out of stock less than 60 days",AC6>=150,"Out of stock more than 150 days") | AF6: =VLOOKUP(C6,'Data Products'!$A:$J,10,0) | AG6: =AF6*F6 | AH6: =IF(J6<=90,F6,0) | AI6: =IFERROR(VLOOKUP(C6,$C$3:$AI$42,34,0),"")
A7: 4 | B7: Active | C7: 1D000JYK00000 | D7: 1D000JYK00000 | E7: 1D000JYK00000 | F7: 884 | G7: 864 | I7: =VLOOKUP(C7,'Data Products'!$A:$B,2,0) | J7: =IFERROR(I7-TODAY(),"") | K7: 45854 | L7: =TODAY()-K7 | M7: 3 | N7: 7 | R7: 0 | S7: 0 | T7: 288 | U7: 288 | V7: 512 | W7: 512 | X7: 20 | Y7: 20 | Z7: 0 | AA7: 0 | AB7: =N7/30 | AC7: =IFERROR(F7/AB7,"-") | AD7: =IFERROR(TODAY()+AC7,"-") | AE7: =_xlfn.IFS(AC7="-","Not sold yet",AND(AC7<=150,AC7>60),"Out of stock more than 60 days",AC7<=60,"Out of stock less than 60 days",AC7>=150,"Out of stock more than 150 days") | AF7: =VLOOKUP(C7,'Data Products'!$A:$J,10,0) | AG7: =AF7*F7 | AH7: =IF(J7<=90,F7,0) | AI7: =IFERROR(VLOOKUP(C7,$C$3:$AI$42,34,0),"")
A8: 5 | B8: Active | C8: 1D000SSK00000 | D8: 1D000SSK00000 | E8: 1D000SSK00000 | F8: 2468 | G8: 2468 | I8: =VLOOKUP(C8,'Data Products'!$A:$B,2,0) | J8: =IFERROR(I8-TODAY(),"") | K8: 45855 | L8: =TODAY()-K8 | M8: 9 | N8: 56 | R8: 0 | S8: 0 | T8: 51 | U8: 51 | V8: 101 | W8: 101 | X8: 0 | Y8: 0 | Z8: 0 | AA8: 0 | AB8: =N8/30 | AC8: =IFERROR(F8/AB8,"-") | AD8: =IFERROR(TODAY()+AC8,"-") | AE8: =_xlfn.IFS(AC8="-","Not sold yet",AND(AC8<=150,AC8>60),"Out of stock more than 60 days",AC8<=60,"Out of stock less than 60 days",AC8>=150,"Out of stock more than 150 days") | AF8: =VLOOKUP(C8,'Data Products'!$A:$J,10,0) | AG8: =AF8*F8 | AH8: =IF(J8<=90,F8,0) | AI8: =IFERROR(VLOOKUP(C8,$C$3:$AI$42,34,0)," ")
A9: 6 | B9: Active | C9: 1D000UBK00000 | D9: 1D000UBK00000 | E9: 1D000UBK00000 | F9: 2062 | G9: 2062 | I9: =VLOOKUP(C9,'Data Products'!$A:$B,2,0) | J9: =IFERROR(I9-TODAY(),"") | K9: 45856 | L9: =TODAY()-K9 | M9: 0 | N9: 0 | R9: 0 | S9: 0 | T9: 1480 | U9: 1478 | V9: 1112 | W9: 1112 | X9: 0 | Y9: 0 | Z9: 0 | AA9: 0 | AB9: =N9/30 | AC9: =IFERROR(F9/AB9,"-") | AD9: =IFERROR(TODAY()+AC9,"-") | AE9: =_xlfn.IFS(AC9="-","Not sold yet",AND(AC9<=150,AC9>60),"Out of stock more than 60 days",AC9<=60,"Out of stock less than 60 days",AC9>=150,"Out of stock more than 150 days") | AF9: =VLOOKUP(C9,'Data Products'!$A:$J,10,0) | AG9: =AF9*F9 | AH9: =IF(J9<=90,F9,0) | AI9: =IFERROR(VLOOKUP(C9,$C$3:$AI$42,34,0),"")
A10: 7 | B10: Active | C10: 1D000WMK00000 | D10: 1D000WMK00000 | E10: 1D000WMK00000 | F10: 479 | G10: 479 | I10: =VLOOKUP(C10,'Data Products'!$A:$B,2,0) | J10: =IFERROR(I10-TODAY(),"") | K10: 45857 | L10: =TODAY()-K10 | M10: 132 | N10: 271 | R10: 0 | S10: 0 | T10: 0 | U10: 0 | V10: 2 | W10: 2 | X10: 0 | Y10: 0 | Z10: 0 | AA10: 0 | AB10: =N10/30 | AC10: =IFERROR(F10/AB10,"-") | AD10: =IFERROR(TODAY()+AC10,"-") | AE10: =_xlfn.IFS(AC10="-","Not sold yet",AND(AC10<=150,AC10>60),"Out of stock more than 60 days",AC10<=60,"Out of stock less than 60 days",AC10>=150,"Out of stock more than 150 days") | AF10: =VLOOKUP(C10,'Data Products'!$A:$J,10,0) | AG10: =AF10*F10 | AH10: =IF(J10<=90,F10,0) | AI10: =IFERROR(VLOOKUP(C10,$C$3:$AI$42,34,0),"")
A11: 8 | B11: Temporary | C11: CNMCU05GBFY05D | D11: CNMCU05GBFY05D | E11: CNMCU05GBFY05D | F11: 1200 | G11: 1200 | I11: =VLOOKUP(C11,'Data Products'!$A:$B,2,0) | J11: =IFERROR(I11-TODAY(),"") | K11: 45858 | L11: =TODAY()-K11 | M11: 0 | N11: 0 | R11: 0 | S11: 0 | T11: 1289 | U11: 1289 | V11: 773 | W11: 773 | X11: 0 | Y11: 0 | Z11: 0 | AA11: 0 | AB11: =N11/30 | AC11: =IFERROR(F11/AB11,"-") | AD11: =IFERROR(TODAY()+AC11,"-") | AE11: =_xlfn.IFS(AC11="-","Not sold yet",AND(AC11<=150,AC11>60),"Out of stock more than 60 days",AC11<=60,"Out of stock less than 60 days",AC11>=150,"Out of stock more than 150 days") | AF11: =VLOOKUP(C11,'Data Products'!$A:$J,10,0) | AG11: =AF11*F11 | AH11: =IF(J11<=90,F11,0) | AI11: =IFERROR(VLOOKUP(C11,$C$3:$AI$42,34,0),"")
A12: 9 | B12: Temporary | C12: CNMCU07GBFY08D | D12: CNMCU07GBFY08D | E12: CNMCU07GBFY08D | F12: 1000 | G12: 1000 | I12: =VLOOKUP(C12,'Data Products'!$A:$B,2,0) | J12: =IFERROR(I12-TODAY(),"") | K12: 45532 | L12: =TODAY()-K12 | M12: 0 | N12: 0 | R12: 0 | S12: 0 | T12: 417 | U12: 416 | V12: 785 | W12: 785 | X12: 0 | Y12: 0 | Z12: 0 | AA12: 0 | AB12: =N12/30 | AC12: =IFERROR(F12/AB12,"-") | AD12: =IFERROR(TODAY()+AC12,"-") | AE12: =_xlfn.IFS(AC12="-","Not sold yet",AND(AC12<=150,AC12>60),"Out of stock more than 60 days",AC12<=60,"Out of stock less than 60 days",AC12>=150,"Out of stock more than 150 days") | AF12: =VLOOKUP(C12,'Data Products'!$A:$J,10,0) | AG12: =AF12*F12 | AH12: =IF(J12<=90,F12,0) | AI12: qua tết push lại, mỗi tuần nhắc lại
A13: 10 | B13: Temporary | C13: KORCU10GBFY05D | D13: KORCU10GBFY05D | E13: KORCU10GBFY05D | F13: 500 | G13: 500 | I13: =VLOOKUP(C13,'Data Products'!$A:$B,2,0) | J13: =IFERROR(I13-TODAY(),"") | K13: 45504 | L13: =TODAY()-K13 | M13: 0 | N13: 0 | R13: 0 | S13: 0 | T13: 3870 | U13: 1017 | V13: 366 | W13: 366 | X13: 0 | Y13: 0 | Z13: 0 | AA13: 0 | AB13: =N13/30 | AC13: =IFERROR(F13/AB13,"-") | AD13: =IFERROR(TODAY()+AC13,"-") | AE13: =_xlfn.IFS(AC13="-","Not sold yet",AND(AC13<=150,AC13>60),"Out of stock more than 60 days",AC13<=60,"Out of stock less than 60 days",AC13>=150,"Out of stock more than 150 days") | AF13: =VLOOKUP(C13,'Data Products'!$A:$J,10,0) | AG13: =AF13*F13 | AH13: =IF(J13<=90,F13,0) | AI13: =IFERROR(VLOOKUP(C13,$C$3:$AI$42,34,0),"")
A14: 11 | B14: Active | C14: 1DCNMCTF00705 | D14: 1DCNMCTF00705 | E14: 1ECNMCTF00705 | F14: 181 | G14: 181 | I14: =VLOOKUP(C14,'Data Products'!$A:$B,2,0) | J14: =IFERROR(I14-TODAY(),"") | K14: 45504 | L14: =TODAY()-K14 | M14: 1 | N14: 1 | R14: 1200 | S14: 1200 | T14: 0 | U14: 0 | V14: 0 | W14: 0 | X14: 0 | Y14: 0 | Z14: 0 | AA14: 0 | AB14: =N14/30 | AC14: =IFERROR(F14/AB14,"-") | AD14: =IFERROR(TODAY()+AC14,"-") | AE14: =_xlfn.IFS(AC14="-","Not sold yet",AND(AC14<=150,AC14>60),"Out of stock more than 60 days",AC14<=60,"Out of stock less than 60 days",AC14>=150,"Out of stock more than 150 days") | AF14: =VLOOKUP(C14,'Data Products'!$A:$J,10,0) | AG14: =AF14*F14 | AH14: =IF(J14<=90,F14,0) | AI14: =IFERROR(VLOOKUP(C14,$C$3:$AI$42,34,0)," ")
A15: 12 | B15: Active | C15: 1DCNMCUF01530 | D15: 1DCNMCUF01530 | E15: 1ECNMCUF01530 | F15: 100 | G15: 100 | I15: =VLOOKUP(C15,'Data Products'!$A:$B,2,0) | J15: =IFERROR(I15-TODAY(),"") | K15: 45648 | L15: =TODAY()-K15 | M15: 4 | N15: 6 | R15: 1000 | S15: 1000 | T15: 0 | U15: 0 | V15: 0 | W15: 0 | X15: 0 | Y15: 0 | Z15: 0 | AA15: 0 | AB15: =N15/30 | AC15: =IFERROR(F15/AB15,"-") | AD15: =IFERROR(TODAY()+AC15,"-") | AE15: =_xlfn.IFS(AC15="-","Not sold yet",AND(AC15<=150,AC15>60),"Out of stock more than 60 days",AC15<=60,"Out of stock less than 60 days",AC15>=150,"Out of stock more than 150 days") | AF15: =VLOOKUP(C15,'Data Products'!$A:$J,10,0) | AG15: =AF15*F15 | AH15: =IF(J15<=90,F15,0) | AI15: =IFERROR(VLOOKUP(C15,$C$3:$AI$42,34,0),"")
A16: 13 | B16: Active | C16: 1DCNMCUF00303 | D16: 1DCNMCUF00303 | E16: 1ECNMCUF00303 | F16: 847 | G16: 847 | I16: =VLOOKUP(C16,'Data Products'!$A:$B,2,0) | J16: =IFERROR(I16-TODAY(),"") | K16: 45504 | L16: =TODAY()-K16 | M16: 101 | N16: 102 | R16: 500 | S16: 500 | T16: 0 | U16: 0 | V16: 0 | W16: 0 | X16: 0 | Y16: 0 | Z16: 0 | AA16: 0 | AB16: =N16/30 | AC16: =IFERROR(F16/AB16,"-") | AD16: =IFERROR(TODAY()+AC16,"-") | AE16: =_xlfn.IFS(AC16="-","Not sold yet",AND(AC16<=150,AC16>60),"Out of stock more than 60 days",AC16<=60,"Out of stock less than 60 days",AC16>=150,"Out of stock more than 150 days") | AF16: =VLOOKUP(C16,'Data Products'!$A:$J,10,0) | AG16: =AF16*F16 | AH16: =IF(J16<=90,F16,0) | AI16: =IFERROR(VLOOKUP(C16,$C$3:$AI$42,34,0),"")
A17: 14 | B17: Active | C17: 1DCNMCUF00505 | D17: 1DCNMCUF00505 | E17: 1ECNMCUF00505 | F17: 0 | G17: 0 | I17: =VLOOKUP(C17,'Data Products'!$A:$B,2,0) | J17: =IFERROR(I17-TODAY(),"") | K17: 45653 | L17: =TODAY()-K17 | M17: 0 | N17: 0 | R17: 0 | S17: 0 | T17: 128 | U17: 128 | V17: 54 | W17: 54 | X17: 0 | Y17: 0 | Z17: 0 | AA17: 0 | AB17: =N17/30 | AC17: =IFERROR(F17/AB17,"-") | AD17: =IFERROR(TODAY()+AC17,"-") | AE17: =_xlfn.IFS(AC17="-","Not sold yet",AND(AC17<=150,AC17>60),"Out of stock more than 60 days",AC17<=60,"Out of stock less than 60 days",AC17>=150,"Out of stock more than 150 days") | AF17: =VLOOKUP(C17,'Data Products'!$A:$J,10,0) | AG17: =AF17*F17 | AH17: =IF(J17<=90,F17,0) | AI17: =IFERROR(VLOOKUP(C17,$C$3:$AI$42,34,0),"")
A18: 15 | B18: Active | C18: 1DTHADTF05010 | D18: 1DTHADTF05010 | E18: 1ETHADTF05010 | F18: 5 | G18: 5 | I18: =VLOOKUP(C18,'Data Products'!$A:$B,2,0) | J18: =IFERROR(I18-TODAY(),"") | K18: 45737 | L18: =TODAY()-K18 | M18: 0 | N18: 0 | R18: 0 | S18: 0 | T18: 0 | U18: 0 | V18: 116 | W18: 116 | X18: 0 | Y18: 0 | Z18: 0 | AA18: 0 | AB18: =N18/30 | AC18: =IFERROR(F18/AB18,"-") | AD18: =IFERROR(TODAY()+AC18,"-") | AE18: =_xlfn.IFS(AC18="-","Not sold yet",AND(AC18<=150,AC18>60),"Out of stock more than 60 days",AC18<=60,"Out of stock less than 60 days",AC18>=150,"Out of stock more than 150 days") | AF18: =VLOOKUP(C18,'Data Products'!$A:$J,10,0) | AG18: =AF18*F18 | AH18: =IF(J18<=90,F18,0)
A19: 16 | B19: Active | C19: 1DWORCBF01030 | D19: 1DWORCBF01030 | E19: 1DWORCBF01030 | F19: 353 | G19: 353 | I19: =VLOOKUP(C19,'Data Products'!$A:$B,2,0) | J19: =IFERROR(I19-TODAY(),"") | K19: 45653 | L19: =TODAY()-K19 | M19: 0 | N19: 83 | R19: 600 | S19: 600 | T19: 100 | U19: 100 | V19: 300 | W19: 300 | X19: 0 | Y19: 0 | Z19: 0 | AA19: 0 | AB19: =N19/30 | AC19: =IFERROR(F19/AB19,"-") | AD19: =IFERROR(TODAY()+AC19,"-") | AE19: =_xlfn.IFS(AC19="-","Not sold yet",AND(AC19<=150,AC19>60),"Out of stock more than 60 days",AC19<=60,"Out of stock less than 60 days",AC19>=150,"Out of stock more than 150 days") | AF19: =VLOOKUP(C19,'Data Products'!$A:$J,10,0) | AG19: =AF19*F19 | AH19: =IF(J19<=90,F19,0)
A20: 17 | B20: Active | C20: 1DTHATMF01507 | D20: 1DTHATMF01507 | E20: 1ETHATMF01507 | F20: 4155 | G20: 4150 | I20: =VLOOKUP(C20,'Data Products'!$A:$B,2,0) | J20: =IFERROR(I20-TODAY(),"") | K20: 45653 | L20: =TODAY()-K20 | M20: 738 | N20: 2961 | R20: 0 | S20: 0 | T20: 27 | U20: 27 | V20: 25 | W20: 25 | X20: 0 | Y20: 0 | Z20: 0 | AA20: 0 | AB20: =N20/30 | AC20: =IFERROR(F20/AB20,"-") | AD20: =IFERROR(TODAY()+AC20,"-") | AE20: =_xlfn.IFS(AC20="-","Not sold yet",AND(AC20<=150,AC20>60),"Out of stock more than 60 days",AC20<=60,"Out of stock less than 60 days",AC20>=150,"Out of stock more than 150 days") | AF20: =VLOOKUP(C20,'Data Products'!$A:$J,10,0) | AG20: =AF20*F20 | AH20: =IF(J20<=90,F20,0) | AI20: cần đầu tháng 9 có hàng mới
A21: 18 | B21: Active | C21: 1DTHATMF05010 | D21: 1DTHATMF05010 | E21: 1ETHATMF05010 | F21: 7632 | G21: 7621 | I21: =VLOOKUP(C21,'Data Products'!$A:$B,2,0) | J21: =IFERROR(I21-TODAY(),"") | K21: 45847 | L21: =TODAY()-K21 | M21: 518 | N21: 854 | R21: 0 | S21: 0 | T21: 113 | U21: 106 | V21: 1097 | W21: 1097 | X21: 5 | Y21: 0 | Z21: 0 | AA21: 0 | AB21: =N21/30 | AC21: =IFERROR(F21/AB21,"-") | AD21: =IFERROR(TODAY()+AC21,"-") | AE21: =_xlfn.IFS(AC21="-","Not sold yet",AND(AC21<=150,AC21>60),"Out of stock more than 60 days",AC21<=60,"Out of stock less than 60 days",AC21>=150,"Out of stock more than 150 days") | AF21: =VLOOKUP(C21,'Data Products'!$A:$J,10,0) | AG21: =AF21*F21 | AH21: =IF(J21<=90,F21,0) | AI21: cần đầu tháng 9 có hàng mới
